<mujoco model="dual_heal">
   <option gravity="0 0 -9.81" />
   <compiler angle="radian" 
   inertiafromgeom="false" 
   discardvisual="false" 
   meshdir="meshes_new/" />

   <statistic center="0.3 0 0.4" extent="1.5"/>

   <asset>
      <texture type="skybox" builtin="gradient" rgb1="0.3 0.5 0.7" rgb2="0 0 0" width="512" height="3072"/>
      <texture type="2d" name="groundplane" builtin="checker" mark="edge" rgb1="0.2 0.3 0.4" rgb2="0.1 0.2 0.3"
         markrgb="0.8 0.8 0.8" width="300" height="300"/>
      <material name="groundplane" texture="groundplane" texuniform="true" texrepeat="5 5" reflectance="0.2"/>
      <mesh name="base_link" file="base_link.STL" />
      <mesh name="link1" file="link_1.STL" />
      <mesh name="link2" file="link_2.STL" />
      <mesh name="link3" file="link_3.STL" />
      <mesh name="link4" file="link_4.STL" />
      <mesh name="link5" file="link_5.STL" />
      <mesh name="end_effector" file="end_effector.STL" />
      <material name="red_material" rgba="1 0 0 1" />
   </asset>

   <worldbody>
      <light pos="0 0 1.5" dir="0 0 -1" directional="true"/>
      <geom name="floor" size="0 0 0.05" type="plane" material="groundplane"/>
      <camera name="scene_3d_view" pos="1 1 1" zaxis="-0 -1 -1"/>

      <!-- Left Arm -->
      <body name="left_base_link" pos="0.2 0 0" euler="0 0 1.5708">
         <geom type="mesh" mesh="base_link" />

         <body name="left_link_1" pos="0 0 0.171">
            <inertial pos="-12.54E-03 -0.04E-03 111.27E-03" 
                      quat="0.704455 -0.0304055 0.0162858 0.70891" 
                      mass="7.92" diaginertia="0.00490984 0.00426023 0.00389513" />
            <joint name="left_joint_1" pos="0 0 0" axis="0 0 1" range="-3.14159 3.14159" frictionloss="0.1" actuatorfrcrange="-10000 10000" />
            <geom type="mesh" rgba="0.75294 0.75294 0.75294 1" mesh="link1" />

            <body name="left_link_2" pos="0 0.0875 0.1498" quat="0.707105 0.707108 0 0">
               <inertial pos="-0.00017021 0.1561 -0.016973" 
                         quat="0.499892 0.50026 -0.499813 0.500035" 
                         mass="1.24" diaginertia="0.0097684 0.0086581 0.0014536" />
               <joint name="left_joint_2" pos="0 0 0" axis="0 0 -1" range="-3.14159 3.14159" frictionloss="0.1" actuatorfrcrange="-10000 10000" />
               <geom type="mesh" rgba="0.75294 0.75294 0.75294 1" mesh="link2" />

               <body name="left_link_3" pos="0 0.3 0" euler="0 0 -1.57">
                  <inertial pos="-7.5516e-07 0 0.073251" 
                            quat="0.495149 0.509997 -0.506629 0.487912" 
                            mass="5.57" diaginertia="0.0048786 0.00425304 0.00369796" />
                  <joint name="left_joint_3" pos="0 0 0" axis="0 0 1" range="-3.14159 3.14159" frictionloss="0.1" actuatorfrcrange="-10000 10000" />
                  <geom type="mesh" rgba="0.75294 0.75294 0.75294 1" mesh="link3" />

                  <body name="left_link_4" pos="0 0.1593 0.0875" euler="-1.57 0 0">
                     <inertial pos="1.3303e-05 0.06 0.10412" 
                               quat="0.313668 0.63349 -0.634256 0.313086" 
                               mass="1.9" diaginertia="0.00162547 0.0014257 0.00104183" />
                     <joint name="left_joint_4" pos="0 0 0" axis="0 0 1" range="-3.14159 3.14159" frictionloss="0.1" actuatorfrcrange="-10000 10000" />
                     <geom type="mesh" rgba="0.75294 0.75294 0.75294 1" mesh="link4" />

                     <body name="left_link_5" pos="0 0.03185 0.16105" euler="0.50951 0 1.57">
                        <inertial pos="-5.6194e-05 -0.046 0.059696" 
                                  quat="0.457117 0.537094 0.438555 0.556994" 
                                  mass="1.78" diaginertia="0.000913478 0.000827593 0.000774169" />
                        <joint name="left_joint_5" pos="0 0 0" axis="0 0 1" range="-3.14159 3.14159" frictionloss="0.1" actuatorfrcrange="-10000 10000" />
                        <geom type="mesh" rgba="0.75294 0.75294 0.75294 1" mesh="link5" />

                        <body name="left_end_effector" pos="0 -0.1227 0.0654" quat="0.707105 0.707108 0 0">
                           <inertial pos="7.0245e-06 -0.00022138 -0.016847" 
                                     quat="-0.0128774 0.707029 0.00995758 0.706998" 
                                     mass="0.001" diaginertia="0.000326122 0.000191249 0.000189678" />
                           <joint name="left_joint_6" pos="0 0 0" axis="0 0 -1" range="-3.14159 3.14159" frictionloss="0.1" actuatorfrcrange="-10000 10000" />
                           <geom type="mesh" rgba="0.75294 0.75294 0.75294 1" mesh="end_effector" />
                        </body>
                     </body>
                  </body>
               </body>
            </body>
         </body>
      </body>

      <!-- Right Arm -->
      <body name="right_base_link" pos="-0.2 0 0" euler="0 0 1.5708">
         <geom type="mesh" mesh="base_link" />

         <body name="right_link_1" pos="0 0 0.171">
            <inertial pos="-12.54E-03 -0.04E-03 111.27E-03" 
                      quat="0.704455 -0.0304055 0.0162858 0.70891" 
                      mass="7.92" diaginertia="0.00490984 0.00426023 0.00389513" />
            <joint name="right_joint_1" pos="0 0 0" axis="0 0 1" range="-3.14159 3.14159" frictionloss="0.1" actuatorfrcrange="-10000 10000" />
            <geom type="mesh" rgba="0.75294 0.75294 0.75294 1" mesh="link1" />

            <body name="right_link_2" pos="0 0.0875 0.1498" quat="0.707105 0.707108 0 0">
               <inertial pos="-0.00017021 0.1561 -0.016973" 
                         quat="0.499892 0.50026 -0.499813 0.500035" 
                         mass="1.24" diaginertia="0.0097684 0.0086581 0.0014536" />
               <joint name="right_joint_2" pos="0 0 0" axis="0 0 -1" range="-3.14159 3.14159" frictionloss="0.1" actuatorfrcrange="-10000 10000" />
               <geom type="mesh" rgba="0.75294 0.75294 0.75294 1" mesh="link2" />

               <body name="right_link_3" pos="0 0.3 0" euler="0 0 -1.57">
                  <inertial pos="-7.5516e-07 0 0.073251" 
                            quat="0.495149 0.509997 -0.506629 0.487912" 
                            mass="5.57" diaginertia="0.0048786 0.00425304 0.00369796" />
                  <joint name="right_joint_3" pos="0 0 0" axis="0 0 1" range="-3.14159 3.14159" frictionloss="0.1" actuatorfrcrange="-10000 10000" />
                  <geom type="mesh" rgba="0.75294 0.75294 0.75294 1" mesh="link3" />

                  <body name="right_link_4" pos="0 0.1593 0.0875" euler="-1.57 0 0">
                     <inertial pos="1.3303e-05 0.06 0.10412" 
                               quat="0.313668 0.63349 -0.634256 0.313086" 
                               mass="1.9" diaginertia="0.00162547 0.0014257 0.00104183" />
                     <joint name="right_joint_4" pos="0 0 0" axis="0 0 1" range="-3.14159 3.14159" frictionloss="0.1" actuatorfrcrange="-10000 10000" />
                     <geom type="mesh" rgba="0.75294 0.75294 0.75294 1" mesh="link4" />

                     <body name="right_link_5" pos="0 0.03185 0.16105" euler="0.50951 0 1.57">
                        <inertial pos="-5.6194e-05 -0.046 0.059696" 
                                  quat="0.457117 0.537094 0.438555 0.556994" 
                                  mass="1.78" diaginertia="0.000913478 0.000827593 0.000774169" />
                        <joint name="right_joint_5" pos="0 0 0" axis="0 0 1" range="-3.14159 3.14159" frictionloss="0.1" actuatorfrcrange="-10000 10000" />
                        <geom type="mesh" rgba="0.75294 0.75294 0.75294 1" mesh="link5" />

                        <body name="right_end_effector" pos="0 -0.1227 0.0654" quat="0.707105 0.707108 0 0">
                           <inertial pos="7.0245e-06 -0.00022138 -0.016847" 
                                     quat="-0.0128774 0.707029 0.00995758 0.706998" 
                                     mass="0.001" diaginertia="0.000326122 0.000191249 0.000189678" />
                           <joint name="right_joint_6" pos="0 0 0" axis="0 0 -1" range="-3.14159 3.14159" frictionloss="0.1" actuatorfrcrange="-10000 10000" />
                           <geom type="mesh" rgba="0.75294 0.75294 0.75294 1" mesh="end_effector" />
                        </body>
                     </body>
                  </body>
               </body>
            </body>
         </body>
      </body>

   <!-- Large box for robots to pick up -->
      <body name="box" pos="0.005 0.36 0.1">
         <joint name="box_joint" type="free" />
         <geom type="box" size="0.105 0.1 0.1" rgba="0.5 0.5 0.5 1" contype="1" conaffinity="1" condim="6" friction="1 0.5 0.5" solref="0.02 1" solimp="0.9 0.95 0.001"/>
         <inertial pos="0 0 0" mass="0.1" fullinertia="0.0001 0.0001 0.0001 0 0 0" />

         <!-- Left Face Site -->
         <site name="right_face_site" pos="-0.105 0 0" size="0.01" type="sphere" rgba="1 0 0 1" />

         <!-- Right Face Site -->
         <site name="left_face_site" pos="0.105 0 0" size="0.01" type="sphere" euler="0 0 3.14159" rgba="0 1 0 1" />
      </body>




   </worldbody>

   <actuator>
      <motor name="left_turret" joint="left_joint_1" />
      <motor name="left_shoulder" joint="left_joint_2" />
      <motor name="left_elbow" joint="left_joint_3" />
      <motor name="left_wrist_1" joint="left_joint_4" />
      <motor name="left_wrist_2" joint="left_joint_5" />
      <motor name="left_wrist_3" joint="left_joint_6" />

      <motor name="right_turret" joint="right_joint_1" />
      <motor name="right_shoulder" joint="right_joint_2" />
      <motor name="right_elbow" joint="right_joint_3" />
      <motor name="right_wrist_1" joint="right_joint_4" />
      <motor name="right_wrist_2" joint="right_joint_5" />
      <motor name="right_wrist_3" joint="right_joint_6" />
   </actuator>

</mujoco>
