<?xml version="1.0" encoding="utf-8" ?>
<!-- This URDF was automatically created by SolidWorks to URDF Exporter! Originally created by Stephen Brawner (brawner@gmail.com) 
     Commit Version: 1.6.0-4-g7f85cfe  Build Version: 1.6.7995.38578
     For more information, please see http://wiki.ros.org/sw_urdf_exporter -->
<robot name="Syncro">
    <link name="base_link">
        <!-- <inertial>
      <origin
        xyz="6.4348E-05 0.00023941 0.057591"
        rpy="0 0 0" />
      <mass
        value="8.887" />
      <inertia
        ixx="0.071494"
        ixy="6.0512E-05"
        ixz="4.3658E-05"
        iyy="0.071704"
        iyz="0.00016377"
        izz="0.11471" />
    </inertial> -->
        <visual>
            <origin xyz="0 0 0" rpy="0 0 0" />
            <geometry>
                <mesh filename="package://addverb_cobot_description/mesh/base_link.STL" />
            </geometry>
            <material name="">
                <color rgba="0.75294 0.75294 0.75294 1" />
            </material>
        </visual>
        <collision>
            <origin xyz="0 0 0" rpy="0 0 0" />
            <geometry>
                <mesh filename="package://addverb_cobot_description/mesh/base_link.STL" />
            </geometry>
        </collision>
        <inertial>
            <mass value="0.1" />
            <origin xyz="0 0 0" rpy="0 0 0" />
            <inertia ixx="0.03" iyy="0.03" izz="0.03" ixy="0.0" ixz="0.0" iyz="0.0" />
        </inertial>
    </link>
    <link name="link_1">
        <inertial>
            <origin xyz="0.0012198 -0.037603 0.14254" rpy="0 0 0" />
            <mass value="15.770" />
            <inertia ixx="0.16427215" ixy="-0.0014816" ixz="0.0024005" iyy="0.12564158" iyz="-0.6302998" izz="0.063066576" />
        </inertial>
        <visual>
            <origin xyz="0 0 0" rpy="0 0 0" />
            <geometry>
                <mesh filename="package://addverb_cobot_description/mesh/link_1.STL" />
            </geometry>
            <material name="">
                <color rgba="0.75294 0.75294 0.75294 1" />
            </material>
        </visual>
        <collision>
            <origin xyz="0 0 0" rpy="0 0 0" />
            <geometry>
                <mesh filename="package://addverb_cobot_description/mesh/link_1.STL" />
            </geometry>
        </collision>
    </link>
    <joint name="Joint_1" type="continuous">
        <origin xyz="-1.0352E-05 -1.4963E-05 0.1915" rpy="0 0 0" />
        <parent link="base_link" />
        <child link="link_1" />
        <axis xyz="0 0 1" />
    </joint>
    <link name="link_2">
        <inertial>
            <origin xyz="0.0056782 0.29725 0.057483" rpy="0 0 0" />
            <mass value="6.8023" />
            <inertia ixx="0.33399" ixy="0.0037604" ixz="-0.00033912" iyy="0.25414112" iyz="-0.00100949" izz="0.34853" />
        </inertial>
        <visual>
            <origin xyz="0 0 0" rpy="0 0 0" />
            <geometry>
                <mesh filename="package://addverb_cobot_description/mesh/link_2.STL" />
            </geometry>
            <material name="">
                <color rgba="0.75294 0.75294 0.75294 1" />
            </material>
        </visual>
        <collision>
            <origin xyz="0 0 0" rpy="0 0 0" />
            <geometry>
                <mesh filename="package://addverb_cobot_description/mesh/link_2.STL" />
            </geometry>
        </collision>
    </link>
    <joint name="Joint_2" type="continuous">
        <origin xyz="0.0061448 -0.1634 0.22501" rpy="1.5708 0 0" />
        <parent link="link_1" />
        <child link="link_2" />
        <axis xyz="0.0 0 1.0" />
    </joint>
    <link name="link_3">
        <inertial>
            <origin xyz="0.040355 0.0022059 0.162" rpy="0 0 0" />
            <mass value="13.254" />
            <inertia ixx="0.2259652" ixy="0.00365445" ixz="0.100295" iyy="0.3028859" iyz="0.0049505" izz="0.1068496" />
        </inertial>
        <visual>
            <origin xyz="0 0 0" rpy="0 0 0" />
            <geometry>
                <mesh filename="package://addverb_cobot_description/mesh/link_3.STL" />
            </geometry>
            <material name="">
                <color rgba="0.75294 0.75294 0.75294 1" />
            </material>
        </visual>
        <collision>
            <origin xyz="0 0 0" rpy="0 0 0" />
            <geometry>
                <mesh filename="package://addverb_cobot_description/mesh/link_3.STL" />
            </geometry>
        </collision>
    </link>
    <joint name="Joint_3" type="continuous">
        <origin xyz="0.0071622 0.59493 -0.00026935" rpy="-3.1416 0 0" />
        <parent link="link_2" />
        <child link="link_3" />
        <axis xyz="0.0 0 1.0" />
    </joint>
    <link name="link_4">
        <inertial>
            <origin xyz="-0.055577 0.020009 0.28489" rpy="0 0 0" />
            <mass value="4.029" />
            <inertia ixx="0.6803544" ixy="-0.00136051" ixz="-0.0136876" iyy="0.7150474" iyz="0.004894966" izz="0.01106415" />
        </inertial>
        <visual>
            <origin xyz="0 0 0" rpy="0 0 0" />
            <geometry>
                <mesh filename="package://addverb_cobot_description/mesh/link_4.STL" />
            </geometry>
            <material name="">
                <color rgba="0.75294 0.75294 0.75294 1" />
            </material>
        </visual>
        <collision>
            <origin xyz="0 0 0" rpy="0 0 0" />
            <geometry>
                <mesh filename="package://addverb_cobot_description/mesh/link_4.STL" />
            </geometry>
        </collision>
    </link>
    <joint name="Joint_4" type="continuous">
        <origin xyz="0.24523 0.011003 0.34096" rpy="1.5332 0 1.5708" />
        <parent link="link_3" />
        <child link="link_4" />
        <axis xyz="0 0 1.0" />
    </joint>
    <link name="link_5">
        <inertial>
            <origin xyz="0.0019 -0.050 0.109" rpy="0 0 0" />
            <mass value="3.00" />
            <inertia ixx="0.0084975" ixy="-0.000002672" ixz="0.000002041" iyy="0.006833386" iyz="-0.002566163" izz="0.004894633" />
        </inertial>
        <visual>
            <origin xyz="0 0 0" rpy="0 0 0" />
            <geometry>
                <mesh filename="package://addverb_cobot_description/mesh/link_5.STL" />
            </geometry>
            <material name="">
                <color rgba="0.75294 0.75294 0.75294 1" />
            </material>
        </visual>
        <collision>
            <origin xyz="0 0 0" rpy="0 0 0" />
            <geometry>
                <mesh filename="package://addverb_cobot_description/mesh/link_5.STL" />
            </geometry>
        </collision>
    </link>
    <joint name="Joint_5" type="continuous">
        <origin xyz="-0.026239 0.013049 0.41" rpy="0.7854 -0.29013 1.5708" />
        <parent link="link_4" />
        <child link="link_5" />
        <axis xyz="0 0 1" />
    </joint>
    <link name="tool">
        <inertial>
            <origin xyz="-0.19801 -0.58657 0.25236" rpy="0 0 0" />
            <mass value="0" />
            <inertia ixx="0" ixy="0" ixz="0" iyy="0" iyz="0" izz="0.000123" />
        </inertial>
        <visual>
            <origin xyz="0 0 0" rpy="0 0 0" />
            <geometry>
                <mesh filename="package://addverb_cobot_description/mesh/end_effector.STL" />
            </geometry>
            <material name="">
                <color rgba="1 1 1 1" />
            </material>
        </visual>
        <collision>
            <origin xyz="0 0 0" rpy="0 0 0" />
            <geometry>
                <mesh filename="package://addverb_cobot_description/mesh/end_effector.STL" />
            </geometry>
        </collision>
    </link>
    <joint name="Joint_6" type="continuous">
        <origin xyz="0 -0.10501 0.1689" rpy="0.76928 0.17762 -0.18049" />
        <parent link="link_5" />
        <child link="tool" />
        <axis xyz="0 0 1" />
    </joint>
    <transmission name="trans_Joint_1">
        <type>transmission_interface/SimpleTransmission</type>
        <joint name="Joint_1">
            <hardwareInterface>hardware_interface/EffortJointInterface</hardwareInterface>
        </joint>
        <actuator name="Joint_1_motor">
            <hardwareInterface>hardware_interface/EffortJointInterface</hardwareInterface>
            <mechanicalReduction>1</mechanicalReduction>
        </actuator>
    </transmission>
    <transmission name="trans_Joint_2">
        <type>transmission_interface/SimpleTransmission</type>
        <joint name="Joint_2">
            <hardwareInterface>hardware_interface/EffortJointInterface</hardwareInterface>
        </joint>
        <actuator name="Joint_2_motor">
            <hardwareInterface>hardware_interface/EffortJointInterface</hardwareInterface>
            <mechanicalReduction>1</mechanicalReduction>
        </actuator>
    </transmission>
    <transmission name="trans_Joint_3">
        <type>transmission_interface/SimpleTransmission</type>
        <joint name="Joint_3">
            <hardwareInterface>hardware_interface/EffortJointInterface</hardwareInterface>
        </joint>
        <actuator name="Joint_3_motor">
            <hardwareInterface>hardware_interface/EffortJointInterface</hardwareInterface>
            <mechanicalReduction>1</mechanicalReduction>
        </actuator>
    </transmission>
    <transmission name="trans_Joint_4">
        <type>transmission_interface/SimpleTransmission</type>
        <joint name="Joint_4">
            <hardwareInterface>hardware_interface/EffortJointInterface</hardwareInterface>
        </joint>
        <actuator name="Joint_4_motor">
            <hardwareInterface>hardware_interface/EffortJointInterface</hardwareInterface>
            <mechanicalReduction>1</mechanicalReduction>
        </actuator>
    </transmission>
    <transmission name="trans_Joint_5">
        <type>transmission_interface/SimpleTransmission</type>
        <joint name="Joint_5">
            <hardwareInterface>hardware_interface/EffortJointInterface</hardwareInterface>
        </joint>
        <actuator name="Joint_5_motor">
            <hardwareInterface>hardware_interface/EffortJointInterface</hardwareInterface>
            <mechanicalReduction>1</mechanicalReduction>
        </actuator>
    </transmission>
    <transmission name="trans_Joint_6">
        <type>transmission_interface/SimpleTransmission</type>
        <joint name="Joint_6">
            <hardwareInterface>hardware_interface/EffortJointInterface</hardwareInterface>
        </joint>
        <actuator name="Joint_6_motor">
            <hardwareInterface>hardware_interface/EffortJointInterface</hardwareInterface>
            <mechanicalReduction>1</mechanicalReduction>
        </actuator>
    </transmission>
    <gazebo>
        <plugin name="gazebo_ros_control" filename="libgazebo_ros_control.so">
            <robotNamespace>/</robotNamespace>
        </plugin>
    </gazebo>
</robot>

